<robot name="my_robot">

<!--................... Link definition ........................-->
  <material name="red">
      <color rgba="0.8 0 0 1"/>
  </material>

  <material name="green">
    <color rgba="0 0.8 0 1"/>
  </material>

  <material name="blue">
    <color rgba="0 0 0.8 1"/>
  </material>

  <material name="yellow">
    <color rgba="0.8 0.8 0 1"/>
  </material>

  <link name="base">
    <visual>
      <geometry>
        <box size="2 2 1"/>
      </geometry>
      <origin rpy="0 0 0" xyz="0 0 0.5"/>
      <material name="red"/>
    </visual>
  </link>

  <link name="link1">
    <visual>
      <geometry>
        <box size="0.5 0.5 3"/>
      </geometry>
      <origin rpy="0 0 0" xyz="0 0 1.5"/>
      <material name="yellow"/>
    </visual>
  </link>
  <link name="link2">
    <visual>
      <geometry>
        <box size="0.5 0.5 3"/>
      </geometry>
      <origin rpy="0 0 0" xyz="0 0 1.5"/>
      <material name="green"/>
    </visual>
  </link>
  <link name="link3">
    <visual>
      <geometry>
        <box size="0.5 0.5 3"/>
      </geometry>
      <origin rpy="0 0 0" xyz="0 0 1.5"/>
      <material name="blue"/>
    </visual>
  </link>

<!--....................Joint Definition........................-->

  <joint name="joint0" type="continuous">
    <parent link="base"/>
    <child link="link1"/>
    <origin rpy="0 0 0" xyz="0 0 0.5"/>
    <axis xyz="0 0 1" />
  </joint>

  <joint name="joint1" type="continuous">
    <parent link="link1"/>
    <child link="link2"/>
    <origin rpy="0 0 0" xyz="0.5 0 2.5"/>
    <axis xyz="1 0 0" />
  </joint>

  <joint name="joint2" type="continuous">
    <parent link="link2"/>
    <child link="link3"/>
    <origin rpy="0 0 0" xyz="-0.5 0 2.5"/>
    <axis xyz="1 0 0" />
  </joint>


</robot>
